Workbook

Sheet PO & Payment Tracker
A1: KHAVDA 442MW SOLAR PROJECT — VENDOR PO & PAYMENT TRACKER
A3: PROJECT: KHAVDA 442MW | DOCUMENT TYPE: RECONCILED PO & VENDOR PAYABLE STATEMENT | DATE: 29-07-2026
B5: TOTAL VENDORS | E5: TOTAL PAID AS ON DATE | H5: TOTAL OUTSTANDING PAYABLE | K5: TOTAL CONTRACT VALUE | M5: OVERALL PAID RATIO
B6: =COUNTA(C10:C53) | E6: =I54 | H6: =J54 | K6: =K54 | M6: =I54/K54
A9: S.No. | B9: Ref Sr. | C9: PO Number | D9: Project Name | E9: Type | F9: Description / Scope | G9: Company / Vendor Firm Name | H9: Vendor Contact / Representative | I9: Paid As On (₹) | J9: Amount to be Paid (₹) | K9: Total Value (₹) | L9: Paid % | M9: Payment Status | N9: Audit / Highlight Notes
A10: 1 | B10: 8 | C10: 6002526032 | D10: KHAVDA 442MW | E10: Service | F10: Piling Work | G10: VIBRANT CONSTRUCTION COMPANY | H10: Mohamad (6360589955) | I10: 8142757 | J10: 500000 | K10: =I10+J10 | L10: =IF(K10>0, I10/K10, 0) | M10: =IF(J10=0,"FULLY PAID",IF(I10=0,"PENDING","PARTIAL"))
A11: 2 | B11: 16 | C11: 6002526062 | D11: KHAVDA 442MW | E11: Service | F11: Erection of MMS | G11: Murlidhar Fabrication | H11: Suresh Kumar (+91 99783 01708) | I11: 2684889 | J11: 1460059 | K11: =I11+J11 | L11: =IF(K11>0, I11/K11, 0) | M11: =IF(J11=0,"FULLY PAID",IF(I11=0,"PENDING","PARTIAL"))
A12: 3 | B12: 17 | C12: 6002526026 | D12: KHAVDA 442MW | E12: Service | F12: Erection of MMS | G12: Choudhary Electric Constrution | H12: Sarvan Choudhary +91 90013 29239 | I12: 8361290 | J12: 2507431 | K12: =I12+J12 | L12: =IF(K12>0, I12/K12, 0) | M12: =IF(J12=0,"FULLY PAID",IF(I12=0,"PENDING","PARTIAL"))
A13: 4 | B13: 22 | C13: 6002526025 | D13: KHAVDA 442MW | E13: Service | F13: Supply Of White Sand | G13: R.K.PROJECT | H13: GAGAL RAMESHBHAI (+91 6354263514) | I13: 5216596 | J13: 24170 | K13: =I13+J13 | L13: =IF(K13>0, I13/K13, 0) | M13: =IF(J13=0,"FULLY PAID",IF(I13=0,"PENDING","PARTIAL"))
A14: 5 | B14: 24 | C14: 6002526050 | D14: KHAVDA 442MW | E14: Service | F14: DG | G14: PALIWAL BUILDING MATERIAL | H14: Lalit- | I14: 1606082 | J14: 250000 | K14: =I14+J14 | L14: =IF(K14>0, I14/K14, 0) | M14: =IF(J14=0,"FULLY PAID",IF(I14=0,"PENDING","PARTIAL"))
A15: 6 | B15: 25 | C15: 6002526051 | D15: KHAVDA 442MW | E15: Service | F15: HT Cable laying | G15: SUPER ELECTRO POWER POONA RAM | H15: Poona ram | I15: 3817310 | J15: 213861 | K15: =I15+J15 | L15: =IF(K15>0, I15/K15, 0) | M15: =IF(J15=0,"FULLY PAID",IF(I15=0,"PENDING","PARTIAL"))
A16: 7 | B16: 27 | C16: 6002526061 | D16: KHAVDA 442MW | E16: Service | F16: VLF Testing | G16: TNM GENIE PRIVATE LIMITED | H16: Saravanakkumar +91 9741402787 | I16: 664070 | J16: 44314 | K16: =I16+J16 | L16: =IF(K16>0, I16/K16, 0) | M16: =IF(J16=0,"FULLY PAID",IF(I16=0,"PENDING","PARTIAL")) | N16: Highlighted Yellow in Statement
A17: 8 | B17: 31 | C17: 6002526072 | D17: KHAVDA 442MW | E17: Service | F17: Erection of MMS | G17: PUSHPA ENTERPRISES | H17: RAM KUMAR (+91 97259 87924) | I17: 2426646 | J17: 222850 | K17: =I17+J17 | L17: =IF(K17>0, I17/K17, 0) | M17: =IF(J17=0,"FULLY PAID",IF(I17=0,"PENDING","PARTIAL"))
A18: 9 | B18: 15 | C18: 6002526084 | D18: KHAVDA 442MW | E18: Service | F18: Erection of MMS | G18: R P CONSTRUCTION | H18: BAYUNANDAN PANDE (92419 50137) | I18: 1651357 | J18: 35435 | K18: =I18+J18 | L18: =IF(K18>0, I18/K18, 0) | M18: =IF(J18=0,"FULLY PAID",IF(I18=0,"PENDING","PARTIAL"))
A19: 10 | B19: 17 | C19: 6002526087 | D19: KHAVDA 442MW | E19: Service | F19: Erection of MMS | G19: AKSHAR CORPORATION | H19: MEHULKUMAR VASUDEVBHAI PATEL | I19: 2636044 | J19: 456175 | K19: =I19+J19 | L19: =IF(K19>0, I19/K19, 0) | M19: =IF(J19=0,"FULLY PAID",IF(I19=0,"PENDING","PARTIAL"))
A20: 11 | B20: 19 | C20: 6002526091 | D20: KHAVDA 442MW | E20: Service | F20: Erection of MMS | G20: ADITYA POWER TECHNOLOGIES | H20: Hemang Patel | I20: 620240 | J20: 428614 | K20: =I20+J20 | L20: =IF(K20>0, I20/K20, 0) | M20: =IF(J20=0,"FULLY PAID",IF(I20=0,"PENDING","PARTIAL"))
A21: 12 | B21: 20 | C21: 6002526092 | D21: KHAVDA 442MW | E21: Service | F21: Erection of MMS | G21: SABNAM ENTERPRISE | H21: SABNAM BANU | I21: 2883657 | J21: 423482 | K21: =I21+J21 | L21: =IF(K21>0, I21/K21, 0) | M21: =IF(J21=0,"FULLY PAID",IF(I21=0,"PENDING","PARTIAL"))
A22: 13 | B22: 27 | C22: 6002526110 | D22: KHAVDA 442MW | E22: Service | F22: Erection of MMS | G22: Polyvision India | H22: Mahesh Ganesh Patel (9819343954) | I22: 1156520 | J22: 300000 | K22: =I22+J22 | L22: =IF(K22>0, I22/K22, 0) | M22: =IF(J22=0,"FULLY PAID",IF(I22=0,"PENDING","PARTIAL"))
A23: 14 | B23: 29 | C23: 6002526112 | D23: KHAVDA 442MW | E23: Service | F23: Erection of MMS | G23: M/S NITYA DEV ENTERPRISES | H23: SANDEEP KUMAR (+91 9992279349, 9467496874) | I23: 236952 | J23: 209366 | K23: =I23+J23 | L23: =IF(K23>0, I23/K23, 0) | M23: =IF(J23=0,"FULLY PAID",IF(I23=0,"PENDING","PARTIAL"))
A24: 15 | B24: 30 | C24: 6002526113 | D24: KHAVDA 442MW | E24: Service | F24: AC-DC Work | G24: TD ELECTRICAL & SOLAR | H24: TAPOMOY DEY: +91 7602143142 | I24: 2280000 | J24: 150000 | K24: =I24+J24 | L24: =IF(K24>0, I24/K24, 0) | M24: =IF(J24=0,"FULLY PAID",IF(I24=0,"PENDING","PARTIAL"))
A25: 16 | B25: 31 | C25: 6002526115 | D25: KHAVDA 442MW | E25: Service | F25: Erection of MMS | G25: Mahadev Infratech Enterprises | H25: Hari Ram 9983414884, 8239971600 | I25: 555841 | J25: 100361 | K25: =I25+J25 | L25: =IF(K25>0, I25/K25, 0) | M25: =IF(J25=0,"FULLY PAID",IF(I25=0,"PENDING","PARTIAL"))
A26: 17 | B26: 32 | C26: 6002526120 | D26: KHAVDA 442MW | E26: Service | F26: LT & Earthing Trench Work | G26: R.K.PROJECT | H26: GAGAL RAMESHBHAI (+91 6354263514) | I26: 0 | J26: 608934 | K26: =I26+J26 | L26: =IF(K26>0, I26/K26, 0) | M26: =IF(J26=0,"FULLY PAID",IF(I26=0,"PENDING","PARTIAL")) | N26: Entire Payment Pending
A27: 18 | B27: 36 | C27: 6002526132 | D27: KHAVDA 442MW | E27: Service | F27: Hiring of Vechile | G27: R.S.B.T. SUPPLIERS | H27: Praveen bhalothia (+91 6005289994, 9879393598) | I27: 1458428 | J27: 496440 | K27: =I27+J27 | L27: =IF(K27>0, I27/K27, 0) | M27: =IF(J27=0,"FULLY PAID",IF(I27=0,"PENDING","PARTIAL"))
A28: 19 | B28: 41 | C28: 6002526145 | D28: KHAVDA 442MW | E28: Service | F28: Erection of MMS | G28: OZONE INFRA | H28: AMIT KUMAR BAJPAI (+91 9554523222) | I28: 1635481 | J28: 908870 | K28: =I28+J28 | L28: =IF(K28>0, I28/K28, 0) | M28: =IF(J28=0,"FULLY PAID",IF(I28=0,"PENDING","PARTIAL"))
A29: 20 | B29: 43 | C29: 6002526152 | D29: KHAVDA 442MW | E29: Service | F29: Erection of MMS | G29: TANSUMAN LIGHTNING ENTERPRISES (OPC) PRIVATE LIMITED | H29: Vishal Rathore (+91 7790909130) | I29: 446072 | J29: 111519 | K29: =I29+J29 | L29: =IF(K29>0, I29/K29, 0) | M29: =IF(J29=0,"FULLY PAID",IF(I29=0,"PENDING","PARTIAL"))
A30: 21 | B30: 51 | C30: - | D30: KHAVDA 442MW | E30: Supplier | F30: Hardware & Machine | G30: Rajkot Machinery | H30: Rajkot Machinery | I30: 1100000 | J30: 130023 | K30: =I30+J30 | L30: =IF(K30>0, I30/K30, 0) | M30: =IF(J30=0,"FULLY PAID",IF(I30=0,"PENDING","PARTIAL")) | N30: Supplier Account
A31: 22 | B31: 57 | C31: - | D31: KHAVDA 442MW | E31: Service | F31: Hiring Splicing Service | G31: New Radiant Enterprises | H31: New Radiant Enterprises | I31: 0 | J31: 61950 | K31: =I31+J31 | L31: =IF(K31>0, I31/K31, 0) | M31: =IF(J31=0,"FULLY PAID",IF(I31=0,"PENDING","PARTIAL")) | N31: Entire Payment Pending
A32: 23 | B32: 5 | C32: 6002526034 | D32: KHAVDA 442MW | E32: Service | F32: IDT Civil | G32: Dayachand -7 | H32: PAWAN KUMAR 80555 27414 | I32: 2740748 | J32: 152263 | K32: =I32+J32 | L32: =IF(K32>0, I32/K32, 0) | M32: =IF(J32=0,"FULLY PAID",IF(I32=0,"PENDING","PARTIAL")) | N32: Highlighted Yellow in Statement
A33: 24 | B33: 7 | C33: 6002526064 | D33: KHAVDA 442MW | E33: Service | F33: IDT Civil | G33: Baburam-3 | H33: BABU RAM (+91 9001678721) | I33: 1160379 | J33: 128931 | K33: =I33+J33 | L33: =IF(K33>0, I33/K33, 0) | M33: =IF(J33=0,"FULLY PAID",IF(I33=0,"PENDING","PARTIAL"))
A34: 25 | B34: 20 | C34: 6002526001 | D34: KHAVDA 442MW | E34: Service | F34: AC-DC Work | G34: J.P. ENTERPRISES | H34: JAI PRAKASH +91 98282 39611 | I34: 3535000 | J34: 200000 | K34: =I34+J34 | L34: =IF(K34>0, I34/K34, 0) | M34: =IF(J34=0,"FULLY PAID",IF(I34=0,"PENDING","PARTIAL"))
A35: 26 | B35: 42 | C35: 6002526027 | D35: KHAVDA 442MW | E35: Service | F35: HT Jointer | G35: Sanjay Kumar Yadav | H35: Sanjay Kumar Yadav | I35: 700000 | J35: 42306 | K35: =I35+J35 | L35: =IF(K35>0, I35/K35, 0) | M35: =IF(J35=0,"FULLY PAID",IF(I35=0,"PENDING","PARTIAL"))
A36: 27 | B36: 50 | C36: 6002526086 | D36: KHAVDA 442MW | E36: Service | F36: Erection of MMS | G36: SARTHAK ENTERPRISES | H36: OM PRAKASH +91 8950588873, 9896098873 | I36: 17118 | J36: 4280 | K36: =I36+J36 | L36: =IF(K36>0, I36/K36, 0) | M36: =IF(J36=0,"FULLY PAID",IF(I36=0,"PENDING","PARTIAL"))
A37: 28 | B37: 77 | C37: 6002526136 | D37: KHAVDA 442MW | E37: Service | F37: AC-DC Work | G37: FATIMA CONSTRUCTION | H37: ZAINAB FATMA 7428270013 | I37: 2200000 | J37: 450000 | K37: =I37+J37 | L37: =IF(K37>0, I37/K37, 0) | M37: =IF(J37=0,"FULLY PAID",IF(I37=0,"PENDING","PARTIAL"))
A38: 29 | B38: 91 | C38: 6002526155 | D38: KHAVDA 442MW | E38: Service | F38: String Work | G38: FATA RAM | H38: FATA RAM (+91 8401688194) | I38: 380700 | J38: 42300 | K38: =I38+J38 | L38: =IF(K38>0, I38/K38, 0) | M38: =IF(J38=0,"FULLY PAID",IF(I38=0,"PENDING","PARTIAL"))
A39: 30 | B39: 95 | C39: 6002526159 | D39: KHAVDA 442MW | E39: Service | F39: Erection of Module | G39: Juhi Gulab | H39: ALHANOOR (+91 8460311858) | I39: 329386 | J39: 93056 | K39: =I39+J39 | L39: =IF(K39>0, I39/K39, 0) | M39: =IF(J39=0,"FULLY PAID",IF(I39=0,"PENDING","PARTIAL")) | N39: Highlighted Yellow in Statement
A40: 31 | B40: 135 | C40: - | D40: KHAVDA 442MW | E40: Service | F40: AC-DC Work | G40: Nagnararai Construction Company-2 | H40: Lun Singh ( 9680881351) | I40: 3220000 | J40: 700000 | K40: =I40+J40 | L40: =IF(K40>0, I40/K40, 0) | M40: =IF(J40=0,"FULLY PAID",IF(I40=0,"PENDING","PARTIAL"))
A41: 32 | B41: 140 | C41: - | D41: KHAVDA 442MW | E41: Service | F41: HT Cable laying | G41: Ashok Kumar Bairwa | H41: Ashok Kumar Bairwa(9740523254) | I41: 350248 | J41: 25000 | K41: =I41+J41 | L41: =IF(K41>0, I41/K41, 0) | M41: =IF(J41=0,"FULLY PAID",IF(I41=0,"PENDING","PARTIAL"))
A42: 33 | B42: 143 | C42: - | D42: KHAVDA 442MW | E42: Service | F42: Supply Labour | G42: Girdhari Ram Labour | H42: Girdhari Ram Labour | I42: 821512 | J42: 300000 | K42: =I42+J42 | L42: =IF(K42>0, I42/K42, 0) | M42: =IF(J42=0,"FULLY PAID",IF(I42=0,"PENDING","PARTIAL"))
A43: 34 | B43: 147 | C43: - | D43: KHAVDA 442MW | E43: Service | F43: DC Works | G43: Sumer Singh | H43: Devi Singh/ Sumer Singh | I43: 1961000 | J43: 700000 | K43: =I43+J43 | L43: =IF(K43>0, I43/K43, 0) | M43: =IF(J43=0,"FULLY PAID",IF(I43=0,"PENDING","PARTIAL"))
A44: 35 | B44: 154 | C44: - | D44: KHAVDA 442MW | E44: Service | F44: AC-DC Work | G44: Jeeshan Ahemad | H44: Jeeshan Ahemad | I44: 1625000 | J44: 100000 | K44: =I44+J44 | L44: =IF(K44>0, I44/K44, 0) | M44: =IF(J44=0,"FULLY PAID",IF(I44=0,"PENDING","PARTIAL"))
...

Sheet Scope & Payment Summary
A1: KHAVDA 442MW — SCOPE OF WORK SUMMARY & PAYMENT BREAKDOWN
A4: Scope / Description | B4: Vendor Count | C4: Total Paid As On (₹) | D4: Total Payable (₹) | E4: Total Contract Value (₹) | F4: Paid %
A5: Erection of MMS | B5: =COUNTIF('PO & Payment Tracker'!F10:F53, "Erection of MMS") | C5: =SUMIF('PO & Payment Tracker'!F10:F53, "Erection of MMS", 'PO & Payment Tracker'!I10:I53) | D5: =SUMIF('PO & Payment Tracker'!F10:F53, "Erection of MMS", 'PO & Payment Tracker'!J10:J53) | E5: =C5+D5 | F5: =IF(E5>0, C5/E5, 0)
A6: AC-DC Work | B6: =COUNTIF('PO & Payment Tracker'!F10:F53, "AC-DC Work") | C6: =SUMIF('PO & Payment Tracker'!F10:F53, "AC-DC Work", 'PO & Payment Tracker'!I10:I53) | D6: =SUMIF('PO & Payment Tracker'!F10:F53, "AC-DC Work", 'PO & Payment Tracker'!J10:J53) | E6: =C6+D6 | F6: =IF(E6>0, C6/E6, 0)
A7: IDT Civil | B7: =COUNTIF('PO & Payment Tracker'!F10:F53, "IDT Civil") | C7: =SUMIF('PO & Payment Tracker'!F10:F53, "IDT Civil", 'PO & Payment Tracker'!I10:I53) | D7: =SUMIF('PO & Payment Tracker'!F10:F53, "IDT Civil", 'PO & Payment Tracker'!J10:J53) | E7: =C7+D7 | F7: =IF(E7>0, C7/E7, 0)
A8: Hiring of Vechile | B8: =COUNTIF('PO & Payment Tracker'!F10:F53, "Hiring of Vechile") | C8: =SUMIF('PO & Payment Tracker'!F10:F53, "Hiring of Vechile", 'PO & Payment Tracker'!I10:I53) | D8: =SUMIF('PO & Payment Tracker'!F10:F53, "Hiring of Vechile", 'PO & Payment Tracker'!J10:J53) | E8: =C8+D8 | F8: =IF(E8>0, C8/E8, 0)
A9: HT Cable laying | B9: =COUNTIF('PO & Payment Tracker'!F10:F53, "HT Cable laying") | C9: =SUMIF('PO & Payment Tracker'!F10:F53, "HT Cable laying", 'PO & Payment Tracker'!I10:I53) | D9: =SUMIF('PO & Payment Tracker'!F10:F53, "HT Cable laying", 'PO & Payment Tracker'!J10:J53) | E9: =C9+D9 | F9: =IF(E9>0, C9/E9, 0)
A10: Piling Work | B10: =COUNTIF('PO & Payment Tracker'!F10:F53, "Piling Work") | C10: =SUMIF('PO & Payment Tracker'!F10:F53, "Piling Work", 'PO & Payment Tracker'!I10:I53) | D10: =SUMIF('PO & Payment Tracker'!F10:F53, "Piling Work", 'PO & Payment Tracker'!J10:J53) | E10: =C10+D10 | F10: =IF(E10>0, C10/E10, 0)
A11: Supply Of White Sand | B11: =COUNTIF('PO & Payment Tracker'!F10:F53, "Supply Of White Sand") | C11: =SUMIF('PO & Payment Tracker'!F10:F53, "Supply Of White Sand", 'PO & Payment Tracker'!I10:I53) | D11: =SUMIF('PO & Payment Tracker'!F10:F53, "Supply Of White Sand", 'PO & Payment Tracker'!J10:J53) | E11: =C11+D11 | F11: =IF(E11>0, C11/E11, 0)
A12: DG | B12: =COUNTIF('PO & Payment Tracker'!F10:F53, "DG") | C12: =SUMIF('PO & Payment Tracker'!F10:F53, "DG", 'PO & Payment Tracker'!I10:I53) | D12: =SUMIF('PO & Payment Tracker'!F10:F53, "DG", 'PO & Payment Tracker'!J10:J53) | E12: =C12+D12 | F12: =IF(E12>0, C12/E12, 0)
A13: VLF Testing | B13: =COUNTIF('PO & Payment Tracker'!F10:F53, "VLF Testing") | C13: =SUMIF('PO & Payment Tracker'!F10:F53, "VLF Testing", 'PO & Payment Tracker'!I10:I53) | D13: =SUMIF('PO & Payment Tracker'!F10:F53, "VLF Testing", 'PO & Payment Tracker'!J10:J53) | E13: =C13+D13 | F13: =IF(E13>0, C13/E13, 0)
A14: LT & Earthing Trench Work | B14: =COUNTIF('PO & Payment Tracker'!F10:F53, "LT & Earthing Trench Work") | C14: =SUMIF('PO & Payment Tracker'!F10:F53, "LT & Earthing Trench Work", 'PO & Payment Tracker'!I10:I53) | D14: =SUMIF('PO & Payment Tracker'!F10:F53, "LT & Earthing Trench Work", 'PO & Payment Tracker'!J10:J53) | E14: =C14+D14 | F14: =IF(E14>0, C14/E14, 0)
A15: Hardware & Machine | B15: =COUNTIF('PO & Payment Tracker'!F10:F53, "Hardware & Machine") | C15: =SUMIF('PO & Payment Tracker'!F10:F53, "Hardware & Machine", 'PO & Payment Tracker'!I10:I53) | D15: =SUMIF('PO & Payment Tracker'!F10:F53, "Hardware & Machine", 'PO & Payment Tracker'!J10:J53) | E15: =C15+D15 | F15: =IF(E15>0, C15/E15, 0)
A16: Hiring Splicing Service | B16: =COUNTIF('PO & Payment Tracker'!F10:F53, "Hiring Splicing Service") | C16: =SUMIF('PO & Payment Tracker'!F10:F53, "Hiring Splicing Service", 'PO & Payment Tracker'!I10:I53) | D16: =SUMIF('PO & Payment Tracker'!F10:F53, "Hiring Splicing Service", 'PO & Payment Tracker'!J10:J53) | E16: =C16+D16 | F16: =IF(E16>0, C16/E16, 0)
A17: HT Jointer | B17: =COUNTIF('PO & Payment Tracker'!F10:F53, "HT Jointer") | C17: =SUMIF('PO & Payment Tracker'!F10:F53, "HT Jointer", 'PO & Payment Tracker'!I10:I53) | D17: =SUMIF('PO & Payment Tracker'!F10:F53, "HT Jointer", 'PO & Payment Tracker'!J10:J53) | E17: =C17+D17 | F17: =IF(E17>0, C17/E17, 0)
A18: String Work | B18: =COUNTIF('PO & Payment Tracker'!F10:F53, "String Work") | C18: =SUMIF('PO & Payment Tracker'!F10:F53, "String Work", 'PO & Payment Tracker'!I10:I53) | D18: =SUMIF('PO & Payment Tracker'!F10:F53, "String Work", 'PO & Payment Tracker'!J10:J53) | E18: =C18+D18 | F18: =IF(E18>0, C18/E18, 0)
A19: Erection of Module | B19: =COUNTIF('PO & Payment Tracker'!F10:F53, "Erection of Module") | C19: =SUMIF('PO & Payment Tracker'!F10:F53, "Erection of Module", 'PO & Payment Tracker'!I10:I53) | D19: =SUMIF('PO & Payment Tracker'!F10:F53, "Erection of Module", 'PO & Payment Tracker'!J10:J53) | E19: =C19+D19 | F19: =IF(E19>0, C19/E19, 0)
A20: Supply Labour | B20: =COUNTIF('PO & Payment Tracker'!F10:F53, "Supply Labour") | C20: =SUMIF('PO & Payment Tracker'!F10:F53, "Supply Labour", 'PO & Payment Tracker'!I10:I53) | D20: =SUMIF('PO & Payment Tracker'!F10:F53, "Supply Labour", 'PO & Payment Tracker'!J10:J53) | E20: =C20+D20 | F20: =IF(E20>0, C20/E20, 0)
A21: DC Works | B21: =COUNTIF('PO & Payment Tracker'!F10:F53, "DC Works") | C21: =SUMIF('PO & Payment Tracker'!F10:F53, "DC Works", 'PO & Payment Tracker'!I10:I53) | D21: =SUMIF('PO & Payment Tracker'!F10:F53, "DC Works", 'PO & Payment Tracker'!J10:J53) | E21: =C21+D21 | F21: =IF(E21>0, C21/E21, 0)
A22: AC Work | B22: =COUNTIF('PO & Payment Tracker'!F10:F53, "AC Work") | C22: =SUMIF('PO & Payment Tracker'!F10:F53, "AC Work", 'PO & Payment Tracker'!I10:I53) | D22: =SUMIF('PO & Payment Tracker'!F10:F53, "AC Work", 'PO & Payment Tracker'!J10:J53) | E22: =C22+D22 | F22: =IF(E22>0, C22/E22, 0)
A23: WATER SUPPLIERS | B23: =COUNTIF('PO & Payment Tracker'!F10:F53, "WATER SUPPLIERS") | C23: =SUMIF('PO & Payment Tracker'!F10:F53, "WATER SUPPLIERS", 'PO & Payment Tracker'!I10:I53) | D23: =SUMIF('PO & Payment Tracker'!F10:F53, "WATER SUPPLIERS", 'PO & Payment Tracker'!J10:J53) | E23: =C23+D23 | F23: =IF(E23>0, C23/E23, 0)
A24: Oger Machine | B24: =COUNTIF('PO & Payment Tracker'!F10:F53, "Oger Machine") | C24: =SUMIF('PO & Payment Tracker'!F10:F53, "Oger Machine", 'PO & Payment Tracker'!I10:I53) | D24: =SUMIF('PO & Payment Tracker'!F10:F53, "Oger Machine", 'PO & Payment Tracker'!J10:J53) | E24: =C24+D24 | F24: =IF(E24>0, C24/E24, 0)
A25: Cabin / Material | B25: =COUNTIF('PO & Payment Tracker'!F10:F53, "Cabin / Material") | C25: =SUMIF('PO & Payment Tracker'!F10:F53, "Cabin / Material", 'PO & Payment Tracker'!I10:I53) | D25: =SUMIF('PO & Payment Tracker'!F10:F53, "Cabin / Material", 'PO & Payment Tracker'!J10:J53) | E25: =C25+D25 | F25: =IF(E25>0, C25/E25, 0)
A26: TOTALS | B26: =SUM(B5:B25) | C26: =SUM(C5:C25) | D26: =SUM(D5:D25) | E26: =SUM(E5:E25) | F26: =C26/E26
